<?xml version="1.0"?>
<robot xmlns:xacro="http://www.ros.org/wiki/xacro" >
  
  <!-- Define material -->
  <material name="white">
    <color rgba="1 1 1 1"/>
  </material>
  
  <material name="orange">
    <color rgba="1 0.3 0.1 1"/>
  </material>

  <material name="blue">
    <color rgba="0.2 0.2 1 1"/>
  </material>
  
  <material name="black">
    <color rgba="0 0 0 1"/>
  </material>

  <!-- JOINT LIST -->
  <joint name="chassis_joint" type="fixed">
    <parent link="base_link"/>
    <child link="chassis"/>
    <origin xyz="-0.1 0 0"/>
  </joint>

  <joint name="left_wheel_joint" type="continuous">
    <parent link="base_link"/>
    <child link="left_wheel"/>
    <origin xyz="0 0.11 0" rpy="-${pi/2} 0 0"/>
    <axis xyz="0 0 1"/>
  </joint>

  <!-- LINK LIST -->
  <link name="base_link"></link>

  <link name="chassis" type="fixed">
    <visual>
      <origin xyz="0.09 0 0.09"/>
      <geometry>
	<box size="0.18 0.18 0.18"/>
      </geometry>
      <material name="white"/>
    </visual>
  </link>
  
  <link name="left_wheel">
    <visual>
      <geometry>
        <cylinder radius="0.0325" length="0.027"/>
      </geometry>
      <material name="black"/>
    </visual>
  </link>

</robot>
